<?xml version="1.0" ?>
<robot name="cessna_c172">
  <link name="body">
    <visual>
      <geometry>
        <mesh filename="./meshes/body.dae"/>
      </geometry>
    </visual>
  </link>
  <link name="left_aileron">
    <visual>
      <geometry>
        <mesh filename="./meshes/left_aileron.dae"/>
      </geometry>
      <origin rpy="-0.04964102434045399 0.0059831523693889554 0.11985146414757691" xyz="1.8825076889571077 -3.5704041557639887 -1.3232078315671387"/>
    </visual>
  </link>
  <link name="left_flap">
    <visual>
      <geometry>
        <mesh filename="./meshes/left_flap.dae"/>
      </geometry>
      <origin rpy="-0.020000000000000004 0.0 0.0" xyz="1.6 -1.5782881037046619 -1.3987160761585398"/>
    </visual>
  </link>
  <link name="right_aileron">
    <visual>
      <geometry>
        <mesh filename="./meshes/right_aileron.dae"/>
      </geometry>
      <origin rpy="0.04964102434045399 0.0059831523693889554 -0.11985146414757691" xyz="1.8825076889571077 3.5704041557639887 -1.3232078315671387"/>
    </visual>
  </link>
  <link name="right_flap">
    <visual>
      <geometry>
        <mesh filename="./meshes/right_flap.dae"/>
      </geometry>
      <origin rpy="0.020000000000000004 0.0 0.0" xyz="1.6 1.5782881037046619 -1.3987160761585398"/>
    </visual>
  </link>
  <link name="elevators">
    <visual>
      <geometry>
        <mesh filename="./meshes/elevators.dae"/>
      </geometry>
      <origin rpy="0.0 0.0 0.0" xyz="5.55 0.0 -0.57"/>
    </visual>
  </link>
  <link name="rudder">
    <visual>
      <geometry>
        <mesh filename="./meshes/rudder.dae"/>
      </geometry>
      <origin rpy="0.0 0.3500000000000001 0.0" xyz="5.096531856107449 0.0 -3.2442815906887557"/>
    </visual>
  </link>
  <link name="propeller">
    <visual>
      <geometry>
        <mesh filename="./meshes/cessna_prop.dae"/>
      </geometry>
    </visual>
  </link>
  <link name="front_wheel">
    <visual>
      <geometry>
        <mesh filename="./meshes/cessna_front_wheel.dae"/>
      </geometry>
      <origin rpy="0.0 0.0 0.0" xyz="-0.712 0.0 0.313"/>
    </visual>
  </link>
  <link name="rear_left_wheel">
    <visual>
      <geometry>
        <mesh filename="./meshes/cessna_rear_left_wheel.dae"/>
      </geometry>
      <origin rpy="0.0 0.0 0.0" xyz="1.0 1.27 0.25"/>
    </visual>
  </link>
  <link name="rear_right_wheel">
    <visual>
      <geometry>
        <mesh filename="./meshes/cessna_rear_right_wheel.dae"/>
      </geometry>
      <origin rpy="0.0 0.0 0.0" xyz="1.0 -1.27 0.25"/>
    </visual>
  </link>
  <joint name="left_flap_joint" type="revolute">
    <parent link="body"/>
    <child link="left_flap"/>
    <origin rpy="0.02 0 0" xyz="-1.6 1.55 1.43"/>
    <axis xyz="0 1 0"/>
    <limit effort="-1" lower="-0.53" upper="0.53" velocity="-1"/>
  </joint>
  <joint name="left_aileron_joint" type="revolute">
    <parent link="body"/>
    <child link="left_aileron"/>
    <origin rpy="0.05 0 -0.12" xyz="-1.45 3.7 1.5"/>
    <axis xyz="0 1 0"/>
    <limit effort="-1" lower="-0.53" upper="0.53" velocity="-1"/>
  </joint>
  <joint name="right_flap_joint" type="revolute">
    <parent link="body"/>
    <child link="right_flap"/>
    <origin rpy="-0.02 0 0" xyz="-1.6 -1.55 1.43"/>
    <axis xyz="0 1 0"/>
    <limit effort="-1" lower="-0.53" upper="0.53" velocity="-1"/>
  </joint>
  <joint name="right_aileron_joint" type="revolute">
    <parent link="body"/>
    <child link="right_aileron"/>
    <origin rpy="-0.05 0 0.12" xyz="-1.45 -3.7 1.5"/>
    <axis xyz="0 1 0"/>
    <limit effort="-1" lower="-0.53" upper="0.53" velocity="-1"/>
  </joint>
  <joint name="elevators_joint" type="revolute">
    <parent link="body"/>
    <child link="elevators"/>
    <origin rpy="0 0 0" xyz="-5.55 0 0.57"/>
    <axis xyz="0 1 0"/>
    <limit effort="-1" lower="-0.53" upper="0.53" velocity="-1"/>
  </joint>
  <joint name="rudder_joint" type="revolute">
    <parent link="body"/>
    <child link="rudder"/>
    <origin rpy="0 -0.35 0" xyz="-5.9 0 1.3"/>
    <axis xyz="0 0 1"/>
    <limit effort="-1" lower="-0.53" upper="0.53" velocity="-1"/>
  </joint>
  <joint name="propeller_joint" type="revolute">
    <parent link="body"/>
    <child link="propeller"/>
    <axis xyz="1 0 0"/>
    <limit effort="-1" lower="-1e+12" upper="1e+12" velocity="-1"/>
    <origin xyz="1.79 0 0.855"/>
  </joint>
  <joint name="front_wheel_joint" type="revolute">
    <parent link="body"/>
    <child link="front_wheel"/>
    <origin rpy="0 0 0" xyz="0.712 0 -0.313"/>
    <axis xyz="0 1 0"/>
    <limit effort="-1" lower="-1e+12" upper="1e+12" velocity="-1"/>
  </joint>
  <joint name="rear_left_wheel_joint" type="revolute">
    <parent link="body"/>
    <child link="rear_left_wheel"/>
    <origin rpy="0 0 0" xyz="-1 -1.27 -0.25"/>
    <axis xyz="0 1 0"/>
    <limit effort="-1" lower="-1e+12" upper="1e+12" velocity="-1"/>
  </joint>
  <joint name="rear_right_wheel_joint" type="revolute">
    <parent link="body"/>
    <child link="rear_right_wheel"/>
    <origin rpy="0 0 0" xyz="-1 1.27 -0.25"/>
    <axis xyz="0 1 0"/>
    <limit effort="-1" lower="-1e+12" upper="1e+12" velocity="-1"/>
  </joint>
</robot>
